Workbook

Sheet Léeme
A1: Oráculo del conjunto de referencia (5.2) del Proyecto 077
A2: Plataforma de gestión de activos financieros. Estadía de Ramon Ernesto Nieblas Mendivil en PluriOne S.A. de C.V. Construido el jueves 15 de octubre de 2026, antes de programar el motor; lo congela un commit en el repositorio.
A4: Qué es
A5: Es el oráculo de la sección 5.2 del SRS: un escenario con un usuario de prueba (oraculo@example.com), dos portafolios (Principal y Secundario), dos intermediarios (Casa A y Casa B), tres instrumentos de demostración (DEMOACC, DEMOETF y DEMOFIB) y cuatro emisiones de CETES (BI261008, BI261105, BI261217 y BI270318), con las cifras que el motor único debe reproducir: costo y resultado no realizado por intermediario, valor de mercado, valuación de CETES (RF-26b), liquidación al vencimiento (RF-26a), serie diaria, TWR y máxima caída.
A6: Cada cifra de este libro es una fórmula visible que parte de las entradas, escritas en azul. Ninguna cifra se calculó fuera de la hoja y se pegó como valor. El libro lo arma genera_libro.py y lo recalcula Excel.
A7: Las mismas cifras se obtuvieron por un segundo camino independiente: calcula_oraculo.py, en Python con decimal de 28 dígitos y algoritmos distintos (costo total por par en un ciclo diario, en vez de kardex y SUMIFS). compara_vias.py las compara una por una; el resultado está en comparacion_vias.csv y en el README.
A8: pytest compara el motor contra esperados/*.csv, que tienen las cifras de Python sin redondear, con las tolerancias de RNF-01: 0.01 en importes y 0.001 puntos porcentuales en TWR y máxima caída; y comprueba los rechazos de rechazos_rf28.csv (hoja Rechazos).
A10: Cómo leerlo
A11: Colores: azul = entrada escrita a mano (de entradas/*.csv); se puede cambiar su valor dentro de la estructura existente (precios, tasas, cantidades, importes, fechas de transacciones). Gris = rótulo de estructura (la fecha, el portafolio, el instrumento y el intermediario de cada fila de Valuación diaria, CETES, Serie, Precios y Posiciones): define qué filas existen y no se edita en la hoja; para agregar pares, fechas, cortes o periodos, o cambiar el inicio o el fin de un periodo, se cambian entradas/*.csv y se regenera el libro con genera_libro.py. Negro = fórmula. Fuente Arial en todo el libro.
A12: Unidades: importes en pesos (MXN), sin redondear (se muestran con 4 decimales). Tasas en por ciento anual. r(t), índices, TWR y caídas como fracción (0.01 = 1 %), con su equivalente en por ciento. P de CETES con 7 decimales.
A13: • Entradas: Parámetros (intervalo, serie, usuario), cortes, periodos, portafolios, intermediarios, instrumentos, fuentes, versiones de licencia, cargas y el calendario completo de días sin operaciones de 2026 (114 fechas).
A14: • Transacciones: T01 a T16 (entradas) y, por fórmula: monto, costo o ingreso por título, aportación A, retiro R y el kardex del costo promedio por par portafolio-instrumento-intermediario.
... A71: Desde la carpeta del oráculo (la del README), con PYTHONIOENCODING=utf-8: python -I -B calcula_oraculo.py → python -B genera_libro.py → powershell.exe -NoProfile -ExecutionPolicy Bypass -File scripts/recalc_excel.ps1 oraculo_5_2.xlsx → python -B compara_vias.py. Los dos que usan openpyxl van sin -I (openpyxl está en el site-packages del usuario, que -I excluye); la carpeta no tiene archivos .py que tapen la biblioteca estándar. La hoja Comprobaciones debe terminar en VERDADERO.

Sheet Entradas
A1: Entradas del oráculo (5.2)
A2: Azul: entrada escrita a mano (de entradas/*.csv). Negro: fórmula. Gris: rótulo de estructura. Las llaves sustitutas (id) las asigna la base; aquí cada fila se liga por llave natural. Una celda vacía en una columna que admite nulos (direccion, obligacion_suprimir) es NULL.
A4: Parámetros (S-09, P-14)
A5: parámetro | B5: valor | C5: descripción
A6: intervalo_semillas_inicio | B6: 46275 | C6: Primer dia del intervalo de las semillas de precios (S-09, P-14); dia de las primeras compras
A7: intervalo_semillas_fin | B7: 46309 | C7: Ultimo dia del intervalo de las semillas de precios (S-09, P-14)
A8: serie_inicio | B8: 46275 | C8: Cierre base de la serie diaria: V(10/09), I = 1
A9: serie_fin | B9: 46309 | C9: Ultimo dia de la serie diaria
A10: usuario_correo | B10: oraculo@example.com | C10: Usuario de prueba con datos ficticios (S-04)
A12: Fechas de corte
A13: fecha_corte | B13: motivo
A14: 46278 | B14: Domingo: se valua con los cierres del 11/09 (criterio 4 de RF-08); P2 aun sin posicion
A15: 46281 | B15: Festivo (DOF 10/12/2025): se valua con los cierres del 15/09; DEMOACC en dos intermediarios (OE-5)
A16: 46303 | B16: Vencimiento de BI261008 y reinversion T16; DEMOFIB sin cierre ese dia (usa el del 07/10)
A17: 46309 | B17: Corte final del periodo
A19: Periodos de TWR y máxima caída | C19: Cambiar el inicio o el fin de un periodo exige editar entradas/periodos.csv y volver a correr genera_libro.py: los bloques diarios de Periodos tienen un largo fijo (Comprobaciones lo verifica).
A20: periodo | B20: portafolio_nombre | C20: inicio | D20: fin | E20: propósito
A21: P1-A | B21: Principal | C21: 46276 | D21: 46309 | E21: Periodo completo (base V(10/09))
A22: P1-B | B22: Principal | C22: 46276 | D22: 46295 | E22: Primer tramo; encadenamiento con P1-C
A23: P1-C | B23: Principal | C23: 46296 | D23: 46309 | E23: Segundo tramo (base V(30/09)); r(01/10) < 0, el maximo es I = 1
A24: P1-D | B24: Principal | C24: 46304 | D24: 46307 | E24: Serie que no baja: maxima caida 0 (criterio 2 de RF-10)
A25: P2-A | B25: Secundario | C25: 46276 | D25: 46309 | E25: Factor 1 con denominador 0 del 11/09 al 13/09; comprobacion por dos caminos
A26: P2-C | B26: Secundario | C26: 46296 | D26: 46309 | E26: Sin flujos (criterio 1 de RF-09)
A28: Portafolios (usuario de prueba, S-04)
A29: usuario_correo | B29: nombre | C29: divisa_base
A30: oraculo@example.com | B30: Principal | C30: MXN
A31: oraculo@example.com | B31: Secundario | C31: MXN
A33: Intermediarios (RF-25)
A34: usuario_correo | B34: nombre
A35: oraculo@example.com | B35: Casa A
A36: oraculo@example.com | B36: Casa B
A38: Instrumentos (instrumento y emision_cetes; RF-04)
A39: clave | B39: nombre | C39: clase_activo | D39: divisa | E39: de_demostracion | F39: vencimiento | G39: valor_nominal | H39: ¿clave válida? (RF-04, RD-04) | I39: ¿marca congruente?
A40: DEMOACC | B40: Acción de demostración | C40: accion | D40: MXN | E40: TRUE | H40: =IF(C40="cetes",A40="BI"&RIGHT(YEAR(F40),2)&RIGHT("0"&MONTH(F40),2)&RIGHT("0"&DAY(F40),2),NOT(AND(LEFT(A40,2)="BI",LEN(A40)=8,ISNUMBER(--MID(A40,3,6))))) -> TRUE | I40: =E40=(C40<>"cetes") -> TRUE
A41: DEMOETF | B41: ETF de demostración | C41: etf | D41: MXN | E41: TRUE | H41: =IF(C41="cetes",A41="BI"&RIGHT(YEAR(F41),2)&RIGHT("0"&MONTH(F41),2)&RIGHT("0"&DAY(F41),2),NOT(AND(LEFT(A41,2)="BI",LEN(A41)=8,ISNUMBER(--MID(A41,3,6))))) -> TRUE | I41: =E41=(C41<>"cetes") -> TRUE
A42: DEMOFIB | B42: FIBRA de demostración | C42: fibra | D42: MXN | E42: TRUE | H42: =IF(C42="cetes",A42="BI"&RIGHT(YEAR(F42),2)&RIGHT("0"&MONTH(F42),2)&RIGHT("0"&DAY(F42),2),NOT(AND(LEFT(A42,2)="BI",LEN(A42)=8,ISNUMBER(--MID(A42,3,6))))) -> TRUE | I42: =E42=(C42<>"cetes") -> TRUE
A43: BI261008 | B43: CETES con vencimiento el 08/10/2026 | C43: cetes | D43: MXN | E43: FALSE | F43: 46303 | G43: 10 | H43: =IF(C43="cetes",A43="BI"&RIGHT(YEAR(F43),2)&RIGHT("0"&MONTH(F43),2)&RIGHT("0"&DAY(F43),2),NOT(AND(LEFT(A43,2)="BI",LEN(A43)=8,ISNUMBER(--MID(A43,3,6))))) -> TRUE | I43: =E43=(C43<>"cetes") -> TRUE
A44: BI261105 | B44: CETES con vencimiento el 05/11/2026 | C44: cetes | D44: MXN | E44: FALSE | F44: 46331 | G44: 10 | H44: =IF(C44="cetes",A44="BI"&RIGHT(YEAR(F44),2)&RIGHT("0"&MONTH(F44),2)&RIGHT("0"&DAY(F44),2),NOT(AND(LEFT(A44,2)="BI",LEN(A44)=8,ISNUMBER(--MID(A44,3,6))))) -> TRUE | I44: =E44=(C44<>"cetes") -> TRUE
A45: BI261217 | B45: CETES con vencimiento el 17/12/2026 | C45: cetes | D45: MXN | E45: FALSE | F45: 46373 | G45: 10 | H45: =IF(C45="cetes",A45="BI"&RIGHT(YEAR(F45),2)&RIGHT("0"&MONTH(F45),2)&RIGHT("0"&DAY(F45),2),NOT(AND(LEFT(A45,2)="BI",LEN(A45)=8,ISNUMBER(--MID(A45,3,6))))) -> TRUE | I45: =E45=(C45<>"cetes") -> TRUE
A46: BI270318 | B46: CETES con vencimiento el 18/03/2027 | C46: cetes | D46: MXN | E46: FALSE | F46: 46464 | G46: 10 | H46: =IF(C46="cetes",A46="BI"&RIGHT(YEAR(F46),2)&RIGHT("0"&MONTH(F46),2)&RIGHT("0"&DAY(F46),2),NOT(AND(LEFT(A46,2)="BI",LEN(A46)=8,ISNUMBER(--MID(A46,3,6))))) -> TRUE | I46: =E46=(C46<>"cetes") -> TRUE
...

Sheet Transacciones
A1: Transacciones (RF-05) y costo promedio por intermediario (RF-08)
A2: A–J: entradas (transaccion de 4.4). K–AF: fórmulas. El kardex (T–Z) procesa cada par portafolio|instrumento|intermediario en orden: fecha, compras antes que ventas (U = orden). Una venta no cambia el costo unitario; con saldo 0 se reinicia. AE–AF: la cuadrícula de Valuación diaria cubre el par y la fecha de la transacción (si se cambia un par a uno sin filas, AF da FALSO).
A4: ref | B4: portafolio_nombre | C4: intermediario_nombre | D4: instrumento_clave | E4: tipo | F4: fecha_concertacion | G4: cantidad | H4: precio | I4: importe_comisiones | J4: propósito | K4: clase_activo | L4: vencimiento | M4: signo | N4: cantidad con signo | O4: monto = títulos × precio | P4: costo por título (compra) | Q4: ingreso por título (venta) | R4: aportación A | S4: retiro R | T4: llave del par | U4: orden (fecha, compras antes que ventas) | V4: saldo previo del par | W4: saldo después | X4: orden de la transacción previa del par | Y4: costo unitario previo | Z4: costo unitario después | AA4: P de RF-26b ese día (CETES) | AB4: ¿precio = P? | AC4: días al vencimiento | AD4: ¿importe < monto? (venta) | AE4: títulos del par en Valuación diaria ese día | AF4: ¿cuadra con el historial?
A5: T01 | B5: Principal | C5: Casa A | D5: DEMOACC | E5: compra | F5: 46275 | G5: 200 | H5: 99.95 | I5: 57.97 | J5: OE-5 (DEMOACC con Casa A); su costo difiere del de Casa B | K5: =INDEX(Entradas!$C$40:$C$46,MATCH(D5,Entradas!$A$40:$A$46,0)) -> accion | L5: =IF(K5="cetes",INDEX(Entradas!$F$40:$F$46,MATCH(D5,Entradas!$A$40:$A$46,0)),"") | M5: =IF(E5="compra",1,-1) -> 1 | N5: =G5*M5 -> 200 | O5: =G5*H5 -> 19990 | P5: =IF(E5="compra",(O5+I5)/G5,"") -> 100.23985 | Q5: =IF(E5="venta",(O5-I5)/G5,"") | R5: =IF(E5="compra",O5+I5,0) -> 20047.97 | S5: =IF(E5="venta",O5-I5,0) -> 0 | T5: =B5&"|"&D5&"|"&C5 -> Principal|DEMOACC|Casa A | U5: =F5*1000+IF(E5="venta",500,0)+ROWS($A$5:A5) -> 46275001 | V5: =SUMIFS($N$5:$N$20,$T$5:$T$20,T5,$U$5:$U$20,"<"&U5) -> 0 | W5: =V5+N5 -> 200 | X5: =_xlfn.MAXIFS($U$5:$U$20,$T$5:$T$20,T5,$U$5:$U$20,"<"&U5) -> 0 | Y5: =IF(X5=0,0,INDEX($Z$4:Z4,MATCH(X5,$U$4:U4,0))) -> 0 | Z5: =IF(E5="compra",(V5*Y5+G5*P5)/W5,IF(W5=0,0,Y5)) -> 100.23985 | AA5: =IF(K5="cetes",SUMIFS(CETES!$AF$5:$AF$95,CETES!$A$5:$A$95,F5,CETES!$B$5:$B$95,D5),"") | AB5: =IF(K5="cetes",H5=AA5,"") | AC5: =IF(K5="cetes",L5-F5,"") | AD5: =IF(E5="venta",I5<O5,"") | AE5: =SUMIFS('Valuación diaria'!$I$5:$I$354,'Valuación diaria'!$E$5:$E$354,T5,'Valuación diaria'!$A$5:$A$354,F5) -> 200 | AF5: =AE5=SUMIFS($N$5:$N$20,$T$5:$T$20,T5,$F$5:$F$20,"<="&F5) -> TRUE
A6: T02 | B6: Principal | C6: Casa B | D6: DEMOETF | E6: compra | F6: 46275 | G6: 100 | H6: 50.05 | I6: 14.51 | J6: Saldo previo del caso de compra y venta el mismo dia (T11 y T12) | K6: =INDEX(Entradas!$C$40:$C$46,MATCH(D6,Entradas!$A$40:$A$46,0)) -> etf | L6: =IF(K6="cetes",INDEX(Entradas!$F$40:$F$46,MATCH(D6,Entradas!$A$40:$A$46,0)),"") | M6: =IF(E6="compra",1,-1) -> 1 | N6: =G6*M6 -> 100 | O6: =G6*H6 -> 5005 | P6: =IF(E6="compra",(O6+I6)/G6,"") -> 50.1951 | Q6: =IF(E6="venta",(O6-I6)/G6,"") | R6: =IF(E6="compra",O6+I6,0) -> 5019.51 | S6: =IF(E6="venta",O6-I6,0) -> 0 | T6: =B6&"|"&D6&"|"&C6 -> Principal|DEMOETF|Casa B | U6: =F6*1000+IF(E6="venta",500,0)+ROWS($A$5:A6) -> 46275002 | V6: =SUMIFS($N$5:$N$20,$T$5:$T$20,T6,$U$5:$U$20,"<"&U6) -> 0 | W6: =V6+N6 -> 100 | X6: =_xlfn.MAXIFS($U$5:$U$20,$T$5:$T$20,T6,$U$5:$U$20,"<"&U6) -> 0 | Y6: =IF(X6=0,0,INDEX($Z$4:Z5,MATCH(X6,$U$4:U5,0))) -> 0 | Z6: =IF(E6="compra",(V6*Y6+G6*P6)/W6,IF(W6=0,0,Y6)) -> 50.1951 | AA6: =IF(K6="cetes",SUMIFS(CETES!$AF$5:$AF$95,CETES!$A$5:$A$95,F6,CETES!$B$5:$B$95,D6),"") | AB6: =IF(K6="cetes",H6=AA6,"") | AC6: =IF(K6="cetes",L6-F6,"") | AD6: =IF(E6="venta",I6<O6,"") | AE6: =SUMIFS('Valuación diaria'!$I$5:$I$354,'Valuación diaria'!$E$5:$E$354,T6,'Valuación diaria'!$A$5:$A$354,F6) -> 100 | AF6: =AE6=SUMIFS($N$5:$N$20,$T$5:$T$20,T6,$F$5:$F$20,"<="&F6) -> TRUE
A7: T03 | B7: Principal | C7: Casa A | D7: BI261008 | E7: compra | F7: 46275 | G7: 1500 | H7: 9.951624 | I7: 0 | J7: CETES en dos intermediarios (Casa A); compra en mercado secundario concertada el 10/09 al P de RF-26b del dia (d = 28, nodo de la colocacion a 28 dias del 10/09) | K7: =INDEX(Entradas!$C$40:$C$46,MATCH(D7,Entradas!$A$40:$A$46,0)) -> cetes | L7: =IF(K7="cetes",INDEX(Entradas!$F$40:$F$46,MATCH(D7,Entradas!$A$40:$A$46,0)),"") -> 46303 | M7: =IF(E7="compra",1,-1) -> 1 | N7: =G7*M7 -> 1500 | O7: =G7*H7 -> 14927.436 | P7: =IF(E7="compra",(O7+I7)/G7,"") -> 9.951624 | Q7: =IF(E7="venta",(O7-I7)/G7,"") | R7: =IF(E7="compra",O7+I7,0) -> 14927.436 | S7: =IF(E7="venta",O7-I7,0) -> 0 | T7: =B7&"|"&D7&"|"&C7 -> Principal|BI261008|Casa A | U7: =F7*1000+IF(E7="venta",500,0)+ROWS($A$5:A7) -> 46275003 | V7: =SUMIFS($N$5:$N$20,$T$5:$T$20,T7,$U$5:$U$20,"<"&U7) -> 0 | W7: =V7+N7 -> 1500 | X7: =_xlfn.MAXIFS($U$5:$U$20,$T$5:$T$20,T7,$U$5:$U$20,"<"&U7) -> 0 | Y7: =IF(X7=0,0,INDEX($Z$4:Z6,MATCH(X7,$U$4:U6,0))) -> 0 | Z7: =IF(E7="compra",(V7*Y7+G7*P7)/W7,IF(W7=0,0,Y7)) -> 9.951624 | AA7: =IF(K7="cetes",SUMIFS(CETES!$AF$5:$AF$95,CETES!$A$5:$A$95,F7,CETES!$B$5:$B$95,D7),"") -> 9.951624 | AB7: =IF(K7="cetes",H7=AA7,"") -> TRUE | AC7: =IF(K7="cetes",L7-F7,"") -> 28 | AD7: =IF(E7="venta",I7<O7,"") | AE7: =SUMIFS('Valuación diaria'!$I$5:$I$354,'Valuación diaria'!$E$5:$E$354,T7,'Valuación diaria'!$A$5:$A$354,F7) -> 1500 | AF7: =AE7=SUMIFS($N$5:$N$20,$T$5:$T$20,T7,$F$5:$F$20,"<="&F7) -> TRUE
A8: T04 | B8: Principal | C8: Casa B | D8: BI261008 | E8: compra | F8: 46275 | G8: 1000 | H8: 9.951624 | I8: 0 | J8: CETES en dos intermediarios (Casa B); compra en mercado secundario concertada el 10/09 al P de RF-26b del dia (d = 28, nodo de la colocacion a 28 dias del 10/09) | K8: =INDEX(Entradas!$C$40:$C$46,MATCH(D8,Entradas!$A$40:$A$46,0)) -> cetes | L8: =IF(K8="cetes",INDEX(Entradas!$F$40:$F$46,MATCH(D8,Entradas!$A$40:$A$46,0)),"") -> 46303 | M8: =IF(E8="compra",1,-1) -> 1 | N8: =G8*M8 -> 1000 | O8: =G8*H8 -> 9951.624 | P8: =IF(E8="compra",(O8+I8)/G8,"") -> 9.951624 | Q8: =IF(E8="venta",(O8-I8)/G8,"") | R8: =IF(E8="compra",O8+I8,0) -> 9951.624 | S8: =IF(E8="venta",O8-I8,0) -> 0 | T8: =B8&"|"&D8&"|"&C8 -> Principal|BI261008|Casa B | U8: =F8*1000+IF(E8="venta",500,0)+ROWS($A$5:A8) -> 46275004 | V8: =SUMIFS($N$5:$N$20,$T$5:$T$20,T8,$U$5:$U$20,"<"&U8) -> 0 | W8: =V8+N8 -> 1000 | X8: =_xlfn.MAXIFS($U$5:$U$20,$T$5:$T$20,T8,$U$5:$U$20,"<"&U8) -> 0 | Y8: =IF(X8=0,0,INDEX($Z$4:Z7,MATCH(X8,$U$4:U7,0))) -> 0 | Z8: =IF(E8="compra",(V8*Y8+G8*P8)/W8,IF(W8=0,0,Y8)) -> 9.951624 | AA8: =IF(K8="cetes",SUMIFS(CETES!$AF$5:$AF$95,CETES!$A$5:$A$95,F8,CETES!$B$5:$B$95,D8),"") -> 9.951624 | AB8: =IF(K8="cetes",H8=AA8,"") -> TRUE | AC8: =IF(K8="cetes",L8-F8,"") -> 28 | AD8: =IF(E8="venta",I8<O8,"") | AE8: =SUMIFS('Valuación diaria'!$I$5:$I$354,'Valuación diaria'!$E$5:$E$354,T8,'Valuación diaria'!$A$5:$A$354,F8) -> 1000 | AF8: =AE8=SUMIFS($N$5:$N$20,$T$5:$T$20,T8,$F$5:$F$20,"<="&F8) -> TRUE
A9: T05 | B9: Principal | C9: Casa A | D9: DEMOFIB | E9: compra | F9: 46276 | G9: 400 | H9: 24.9825 | I9: 28.98 | J9: Primer flujo dentro del periodo | K9: =INDEX(Entradas!$C$40:$C$46,MATCH(D9,Entradas!$A$40:$A$46,0)) -> fibra | L9: =IF(K9="cetes",INDEX(Entradas!$F$40:$F$46,MATCH(D9,Entradas!$A$40:$A$46,0)),"") | M9: =IF(E9="compra",1,-1) -> 1 | N9: =G9*M9 -> 400 | O9: =G9*H9 -> 9993 | P9: =IF(E9="compra",(O9+I9)/G9,"") -> 25.05495 | Q9: =IF(E9="venta",(O9-I9)/G9,"") | R9: =IF(E9="compra",O9+I9,0) -> 10021.98 | S9: =IF(E9="venta",O9-I9,0) -> 0 | T9: =B9&"|"&D9&"|"&C9 -> Principal|DEMOFIB|Casa A | U9: =F9*1000+IF(E9="venta",500,0)+ROWS($A$5:A9) -> 46276005 | V9: =SUMIFS($N$5:$N$20,$T$5:$T$20,T9,$U$5:$U$20,"<"&U9) -> 0 | W9: =V9+N9 -> 400 | X9: =_xlfn.MAXIFS($U$5:$U$20,$T$5:$T$20,T9,$U$5:$U$20,"<"&U9) -> 0 | Y9: =IF(X9=0,0,INDEX($Z$4:Z8,MATCH(X9,$U$4:U8,0))) -> 0 | Z9: =IF(E9="compra",(V9*Y9+G9*P9)/W9,IF(W9=0,0,Y9)) -> 25.05495 | AA9: =IF(K9="cetes",SUMIFS(CETES!$AF$5:$AF$95,CETES!$A$5:$A$95,F9,CETES!$B$5:$B$95,D9),"") | AB9: =IF(K9="cetes",H9=AA9,"") | AC9: =IF(K9="cetes",L9-F9,"") | AD9: =IF(E9="venta",I9<O9,"") | AE9: =SUMIFS('Valuación diaria'!$I$5:$I$354,'Valuación diaria'!$E$5:$E$354,T9,'Valuación diaria'!$A$5:$A$354,F9) -> 400 | AF9: =AE9=SUMIFS($N$5:$N$20,$T$5:$T$20,T9,$F$5:$F$20,"<="&F9) -> TRUE
A10: T06 | B10: Principal | C10: Casa B | D10: DEMOACC | E10: compra | F10: 46279 | G10: 100 | H10: 103.1 | I10: 29.9 | J10: OE-5 (DEMOACC con Casa B) | K10: =INDEX(Entradas!$C$40:$C$46,MATCH(D10,Entradas!$A$40:$A$46,0)) -> accion | L10: =IF(K10="cetes",INDEX(Entradas!$F$40:$F$46,MATCH(D10,Entradas!$A$40:$A$46,0)),"") | M10: =IF(E10="compra",1,-1) -> 1 | N10: =G10*M10 -> 100 | O10: =G10*H10 -> 10310 | P10: =IF(E10="compra",(O10+I10)/G10,"") -> 103.399 | Q10: =IF(E10="venta",(O10-I10)/G10,"") | R10: =IF(E10="compra",O10+I10,0) -> 10339.9 | S10: =IF(E10="venta",O10-I10,0) -> 0 | T10: =B10&"|"&D10&"|"&C10 -> Principal|DEMOACC|Casa B | U10: =F10*1000+IF(E10="venta",500,0)+ROWS($A$5:A10) -> 46279006 | V10: =SUMIFS($N$5:$N$20,$T$5:$T$20,T10,$U$5:$U$20,"<"&U10) -> 0 | W10: =V10+N10 -> 100 | X10: =_xlfn.MAXIFS($U$5:$U$20,$T$5:$T$20,T10,$U$5:$U$20,"<"&U10) -> 0 | Y10: =IF(X10=0,0,INDEX($Z$4:Z9,MATCH(X10,$U$4:U9,0))) -> 0 | Z10: =IF(E10="compra",(V10*Y10+G10*P10)/W10,IF(W10=0,0,Y10)) -> 103.399 | AA10: =IF(K10="cetes",SUMIFS(CETES!$AF$5:$AF$95,CETES!$A$5:$A$95,F10,CETES!$B$5:$B$95,D10),"") | AB10: =IF(K10="cetes",H10=AA10,"") | AC10: =IF(K10="cetes",L10-F10,"") | AD10: =IF(E10="venta",I10<O10,"") | AE10: =SUMIFS('Valuación diaria'!$I$5:$I$354,'Valuación diaria'!$E$5:$E$354,T10,'Valuación diaria'!$A$5:$A$354,F10) -> 100 | AF10: =AE10=SUMIFS($N$5:$N$20,$T$5:$T$20,T10,$F$5:$F$20,"<="&F10) -> TRUE
A11: T07 | B11: Secundario | C11: Casa A | D11: DEMOACC | E11: compra | F11: 46279 | G11: 150 | H11: 103.6 | I11: 45.07 | J11: X-06: mismo instrumento e intermediario que en Principal, otro portafolio | K11: =INDEX(Entradas!$C$40:$C$46,MATCH(D11,Entradas!$A$40:$A$46,0)) -> accion | L11: =IF(K11="cetes",INDEX(Entradas!$F$40:$F$46,MATCH(D11,Entradas!$A$40:$A$46,0)),"") | M11: =IF(E11="compra",1,-1) -> 1 | N11: =G11*M11 -> 150 | O11: =G11*H11 -> 15540 | P11: =IF(E11="compra",(O11+I11)/G11,"") -> 103.90047 | Q11: =IF(E11="venta",(O11-I11)/G11,"") | R11: =IF(E11="compra",O11+I11,0) -> 15585.07 | S11: =IF(E11="venta",O11-I11,0) -> 0 | T11: =B11&"|"&D11&"|"&C11 -> Secundario|DEMOACC|Casa A | U11: =F11*1000+IF(E11="venta",500,0)+ROWS($A$5:A11) -> 46279007 | V11: =SUMIFS($N$5:$N$20,$T$5:$T$20,T11,$U$5:$U$20,"<"&U11) -> 0 | W11: =V11+N11 -> 150 | X11: =_xlfn.MAXIFS($U$5:$U$20,$T$5:$T$20,T11,$U$5:$U$20,"<"&U11) -> 0 | Y11: =IF(X11=0,0,INDEX($Z$4:Z10,MATCH(X11,$U$4:U10,0))) -> 0 | Z11: =IF(E11="compra",(V11*Y11+G11*P11)/W11,IF(W11=0,0,Y11)) -> 103.90047 | AA11: =IF(K11="cetes",SUMIFS(CETES!$AF$5:$AF$95,CETES!$A$5:$A$95,F11,CETES!$B$5:$B$95,D11),"") | AB11: =IF(K11="cetes",H11=AA11,"") | AC11: =IF(K11="cetes",L11-F11,"") | AD11: =IF(E11="venta",I11<O11,"") | AE11: =SUMIFS('Valuación diaria'!$I$5:$I$354,'Valuación diaria'!$E$5:$E$354,T11,'Valuación diaria'!$A$5:$A$354,F11) -> 150 | AF11: =AE11=SUMIFS($N$5:$N$20,$T$5:$T$20,T11,$F$5:$F$20,"<="&F11) -> TRUE
A12: T08 | B12: Principal | C12: Casa A | D12: BI261217 | E12: compra | F12: 46282 | G12: 1000 | H12: 9.8344372 | I12: 0 | J12: Interpolacion entre 28 y 91 dias; compra en mercado secundario concertada el 17/09 al P de RF-26b del dia (d = 91, nodo de la colocacion a 91 dias del 17/09) | K12: =INDEX(Entradas!$C$40:$C$46,MATCH(D12,Entradas!$A$40:$A$46,0)) -> cetes | L12: =IF(K12="cetes",INDEX(Entradas!$F$40:$F$46,MATCH(D12,Entradas!$A$40:$A$46,0)),"") -> 46373 | M12: =IF(E12="compra",1,-1) -> 1 | N12: =G12*M12 -> 1000 | O12: =G12*H12 -> 9834.4372 | P12: =IF(E12="compra",(O12+I12)/G12,"") -> 9.8344372 | Q12: =IF(E12="venta",(O12-I12)/G12,"") | R12: =IF(E12="compra",O12+I12,0) -> 9834.4372 | S12: =IF(E12="venta",O12-I12,0) -> 0 | T12: =B12&"|"&D12&"|"&C12 -> Principal|BI261217|Casa A | U12: =F12*1000+IF(E12="venta",500,0)+ROWS($A$5:A12) -> 46282008 | V12: =SUMIFS($N$5:$N$20,$T$5:$T$20,T12,$U$5:$U$20,"<"&U12) -> 0 | W12: =V12+N12 -> 1000 | X12: =_xlfn.MAXIFS($U$5:$U$20,$T$5:$T$20,T12,$U$5:$U$20,"<"&U12) -> 0 | Y12: =IF(X12=0,0,INDEX($Z$4:Z11,MATCH(X12,$U$4:U11,0))) -> 0 | Z12: =IF(E12="compra",(V12*Y12+G12*P12)/W12,IF(W12=0,0,Y12)) -> 9.8344372 | AA12: =IF(K12="cetes",SUMIFS(CETES!$AF$5:$AF$95,CETES!$A$5:$A$95,F12,CETES!$B$5:$B$95,D12),"") -> 9.8344372 | AB12: =IF(K12="cetes",H12=AA12,"") -> TRUE | AC12: =IF(K12="cetes",L12-F12,"") -> 91 | AD12: =IF(E12="venta",I12<O12,"") | AE12: =SUMIFS('Valuación diaria'!$I$5:$I$354,'Valuación diaria'!$E$5:$E$354,T12,'Valuación diaria'!$A$5:$A$354,F12) -> 1000 | AF12: =AE12=SUMIFS($N$5:$N$20,$T$5:$T$20,T12,$F$5:$F$20,"<="&F12) -> TRUE
A13: T09 | B13: Principal | C13: Casa B | D13: BI270318 | E13: compra | F13: 46282 | G13: 500 | H13: 9.662925 | I13: 0 | J13: Interpolacion entre 91 y 182 o 175 efectivos; compra en mercado secundario concertada el 17/09 al P de RF-26b del dia (d = 182, nodo de la colocacion a 182 dias del 17/09) | K13: =INDEX(Entradas!$C$40:$C$46,MATCH(D13,Entradas!$A$40:$A$46,0)) -> cetes | L13: =IF(K13="cetes",INDEX(Entradas!$F$40:$F$46,MATCH(D13,Entradas!$A$40:$A$46,0)),"") -> 46464 | M13: =IF(E13="compra",1,-1) -> 1 | N13: =G13*M13 -> 500 | O13: =G13*H13 -> 4831.4625 | P13: =IF(E13="compra",(O13+I13)/G13,"") -> 9.662925 | Q13: =IF(E13="venta",(O13-I13)/G13,"") | R13: =IF(E13="compra",O13+I13,0) -> 4831.4625 | S13: =IF(E13="venta",O13-I13,0) -> 0 | T13: =B13&"|"&D13&"|"&C13 -> Principal|BI270318|Casa B | U13: =F13*1000+IF(E13="venta",500,0)+ROWS($A$5:A13) -> 46282009 | V13: =SUMIFS($N$5:$N$20,$T$5:$T$20,T13,$U$5:$U$20,"<"&U13) -> 0 | W13: =V13+N13 -> 500 | X13: =_xlfn.MAXIFS($U$5:$U$20,$T$5:$T$20,T13,$U$5:$U$20,"<"&U13) -> 0 | Y13: =IF(X13=0,0,INDEX($Z$4:Z12,MATCH(X13,$U$4:U12,0))) -> 0 | Z13: =IF(E13="compra",(V13*Y13+G13*P13)/W13,IF(W13=0,0,Y13)) -> 9.662925 | AA13: =IF(K13="cetes",SUMIFS(CETES!$AF$5:$AF$95,CETES!$A$5:$A$95,F13,CETES!$B$5:$B$95,D13),"") -> 9.662925 | AB13: =IF(K13="cetes",H13=AA13,"") -> TRUE | AC13: =IF(K13="cetes",L13-F13,"") -> 182 | AD13: =IF(E13="venta",I13<O13,"") | AE13: =SUMIFS('Valuación diaria'!$I$5:$I$354,'Valuación diaria'!$E$5:$E$354,T13,'Valuación diaria'!$A$5:$A$354,F13) -> 500 | AF13: =AE13=SUMIFS($N$5:$N$20,$T$5:$T$20,T13,$F$5:$F$20,"<="&F13) -> TRUE
A14: T10 | B14: Principal | C14: Casa A | D14: DEMOFIB | E14: venta | F14: 46287 | G14: 400 | H14: 23.2075 | I14: 26.92 | J14: Venta total: el saldo queda en 0 y el costo se reinicia | K14: =INDEX(Entradas!$C$40:$C$46,MATCH(D14,Entradas!$A$40:$A$46,0)) -> fibra | L14: =IF(K14="cetes",INDEX(Entradas!$F$40:$F$46,MATCH(D14,Entradas!$A$40:$A$46,0)),"") | M14: =IF(E14="compra",1,-1) -> -1 | N14: =G14*M14 -> -400 | O14: =G14*H14 -> 9283 | P14: =IF(E14="compra",(O14+I14)/G14,"") | Q14: =IF(E14="venta",(O14-I14)/G14,"") -> 23.1402 | R14: =IF(E14="compra",O14+I14,0) -> 0 | S14: =IF(E14="venta",O14-I14,0) -> 9256.08 | T14: =B14&"|"&D14&"|"&C14 -> Principal|DEMOFIB|Casa A | U14: =F14*1000+IF(E14="venta",500,0)+ROWS($A$5:A14) -> 46287510 | V14: =SUMIFS($N$5:$N$20,$T$5:$T$20,T14,$U$5:$U$20,"<"&U14) -> 400 | W14: =V14+N14 -> 0 | X14: =_xlfn.MAXIFS($U$5:$U$20,$T$5:$T$20,T14,$U$5:$U$20,"<"&U14) -> 46276005 | Y14: =IF(X14=0,0,INDEX($Z$4:Z13,MATCH(X14,$U$4:U13,0))) -> 25.05495 | Z14: =IF(E14="compra",(V14*Y14+G14*P14)/W14,IF(W14=0,0,Y14)) -> 0 | AA14: =IF(K14="cetes",SUMIFS(CETES!$AF$5:$AF$95,CETES!$A$5:$A$95,F14,CETES!$B$5:$B$95,D14),"") | AB14: =IF(K14="cetes",H14=AA14,"") | AC14: =IF(K14="cetes",L14-F14,"") | AD14: =IF(E14="venta",I14<O14,"") -> TRUE | AE14: =SUMIFS('Valuación diaria'!$I$5:$I$354,'Valuación diaria'!$E$5:$E$354,T14,'Valuación diaria'!$A$5:$A$354,F14) -> 0 | AF14: =AE14=SUMIFS($N$5:$N$20,$T$5:$T$20,T14,$F$5:$F$20,"<="&F14) -> TRUE
A15: T11 | B15: Principal | C15: Casa B | D15: DEMOETF | E15: compra | F15: 46290 | G15: 60 | H15: 47.9 | I15: 8.33 | J15: Compra y venta el mismo dia (compras antes que ventas) | K15: =INDEX(Entradas!$C$40:$C$46,MATCH(D15,Entradas!$A$40:$A$46,0)) -> etf | L15: =IF(K15="cetes",INDEX(Entradas!$F$40:$F$46,MATCH(D15,Entradas!$A$40:$A$46,0)),"") | M15: =IF(E15="compra",1,-1) -> 1 | N15: =G15*M15 -> 60 | O15: =G15*H15 -> 2874 | P15: =IF(E15="compra",(O15+I15)/G15,"") -> 48.038833 | Q15: =IF(E15="venta",(O15-I15)/G15,"") | R15: =IF(E15="compra",O15+I15,0) -> 2882.33 | S15: =IF(E15="venta",O15-I15,0) -> 0 | T15: =B15&"|"&D15&"|"&C15 -> Principal|DEMOETF|Casa B | U15: =F15*1000+IF(E15="venta",500,0)+ROWS($A$5:A15) -> 46290011 | V15: =SUMIFS($N$5:$N$20,$T$5:$T$20,T15,$U$5:$U$20,"<"&U15) -> 100 | W15: =V15+N15 -> 160 | X15: =_xlfn.MAXIFS($U$5:$U$20,$T$5:$T$20,T15,$U$5:$U$20,"<"&U15) -> 46275002 | Y15: =IF(X15=0,0,INDEX($Z$4:Z14,MATCH(X15,$U$4:U14,0))) -> 50.1951 | Z15: =IF(E15="compra",(V15*Y15+G15*P15)/W15,IF(W15=0,0,Y15)) -> 49.3865 | AA15: =IF(K15="cetes",SUMIFS(CETES!$AF$5:$AF$95,CETES!$A$5:$A$95,F15,CETES!$B$5:$B$95,D15),"") | AB15: =IF(K15="cetes",H15=AA15,"") | AC15: =IF(K15="cetes",L15-F15,"") | AD15: =IF(E15="venta",I15<O15,"") | AE15: =SUMIFS('Valuación diaria'!$I$5:$I$354,'Valuación diaria'!$E$5:$E$354,T15,'Valuación diaria'!$A$5:$A$354,F15) -> 40 | AF15: =AE15=SUMIFS($N$5:$N$20,$T$5:$T$20,T15,$F$5:$F$20,"<="&F15) -> TRUE
A16: T12 | B16: Principal | C16: Casa B | D16: DEMOETF | E16: venta | F16: 46290 | G16: 120 | H16: 48.1 | I16: 16.74 | J16: Venta de 120 > saldo previo de 100; solo es valida aplicando antes T11 | K16: =INDEX(Entradas!$C$40:$C$46,MATCH(D16,Entradas!$A$40:$A$46,0)) -> etf | L16: =IF(K16="cetes",INDEX(Entradas!$F$40:$F$46,MATCH(D16,Entradas!$A$40:$A$46,0)),"") | M16: =IF(E16="compra",1,-1) -> -1 | N16: =G16*M16 -> -120 | O16: =G16*H16 -> 5772 | P16: =IF(E16="compra",(O16+I16)/G16,"") | Q16: =IF(E16="venta",(O16-I16)/G16,"") -> 47.9605 | R16: =IF(E16="compra",O16+I16,0) -> 0 | S16: =IF(E16="venta",O16-I16,0) -> 5755.26 | T16: =B16&"|"&D16&"|"&C16 -> Principal|DEMOETF|Casa B | U16: =F16*1000+IF(E16="venta",500,0)+ROWS($A$5:A16) -> 46290512 | V16: =SUMIFS($N$5:$N$20,$T$5:$T$20,T16,$U$5:$U$20,"<"&U16) -> 160 | W16: =V16+N16 -> 40 | X16: =_xlfn.MAXIFS($U$5:$U$20,$T$5:$T$20,T16,$U$5:$U$20,"<"&U16) -> 46290011 | Y16: =IF(X16=0,0,INDEX($Z$4:Z15,MATCH(X16,$U$4:U15,0))) -> 49.3865 | Z16: =IF(E16="compra",(V16*Y16+G16*P16)/W16,IF(W16=0,0,Y16)) -> 49.3865 | AA16: =IF(K16="cetes",SUMIFS(CETES!$AF$5:$AF$95,CETES!$A$5:$A$95,F16,CETES!$B$5:$B$95,D16),"") | AB16: =IF(K16="cetes",H16=AA16,"") | AC16: =IF(K16="cetes",L16-F16,"") | AD16: =IF(E16="venta",I16<O16,"") -> TRUE | AE16: =SUMIFS('Valuación diaria'!$I$5:$I$354,'Valuación diaria'!$E$5:$E$354,T16,'Valuación diaria'!$A$5:$A$354,F16) -> 40 | AF16: =AE16=SUMIFS($N$5:$N$20,$T$5:$T$20,T16,$F$5:$F$20,"<="&F16) -> TRUE
... A20: T16 | B20: Principal | C20: Casa B | D20: BI261105 | E20: compra | F20: 46303 | G20: 1000 | H20: 9.9528566 | I20: 0 | J20: Reinversion registrada como compra (S-14), en mercado secundario concertada el 08/10 al P de RF-26b del dia (d = 28, nodo de la colocacion a 28 dias del 08/10) | K20: =INDEX(Entradas!$C$40:$C$46,MATCH(D20,Entradas!$A$40:$A$46,0)) -> cetes | L20: =IF(K20="cetes",INDEX(Entradas!$F$40:$F$46,MATCH(D20,Entradas!$A$40:$A$46,0)),"") -> 46331 | M20: =IF(E20="compra",1,-1) -> 1 | N20: =G20*M20 -> 1000 | O20: =G20*H20 -> 9952.8566 | P20: =IF(E20="compra",(O20+I20)/G20,"") -> 9.9528566 | Q20: =IF(E20="venta",(O20-I20)/G20,"") | R20: =IF(E20="compra",O20+I20,0) -> 9952.8566 | S20: =IF(E20="venta",O20-I20,0) -> 0 | T20: =B20&"|"&D20&"|"&C20 -> Principal|BI261105|Casa B | U20: =F20*1000+IF(E20="venta",500,0)+ROWS($A$5:A20) -> 46303016 | V20: =SUMIFS($N$5:$N$20,$T$5:$T$20,T20,$U$5:$U$20,"<"&U20) -> 0 | W20: =V20+N20 -> 1000 | X20: =_xlfn.MAXIFS($U$5:$U$20,$T$5:$T$20,T20,$U$5:$U$20,"<"&U20) -> 0 | Y20: =IF(X20=0,0,INDEX($Z$4:Z19,MATCH(X20,$U$4:U19,0))) -> 0 | Z20: =IF(E20="compra",(V20*Y20+G20*P20)/W20,IF(W20=0,0,Y20)) -> 9.9528566 | AA20: =IF(K20="cetes",SUMIFS(CETES!$AF$5:$AF$95,CETES!$A$5:$A$95,F20,CETES!$B$5:$B$95,D20),"") -> 9.9528566 | AB20: =IF(K20="cetes",H20=AA20,"") -> TRUE | AC20: =IF(K20="cetes",L20-F20,"") -> 28 | AD20: =IF(E20="venta",I20<O20,"") | AE20: =SUMIFS('Valuación diaria'!$I$5:$I$354,'Valuación diaria'!$E$5:$E$354,T20,'Valuación diaria'!$A$5:$A$354,F20) -> 1000 | AF20: =AE20=SUMIFS($N$5:$N$20,$T$5:$T$20,T20,$F$5:$F$20,"<="&F20) -> TRUE

Sheet Precios
A1: Precios de cierre sintéticos (RF-07) y cierre usado cada día
A2: Fuente: semilla sintética de demostración del 077 (no son precios reales; R-04, R-05). Solo días con operaciones de 2026; DEMOFIB no tiene cierre el 08/10 a propósito. I–M: último cierre igual o anterior a cada día natural (criterio 4 de RF-08); I y J son rótulos de estructura (gris).
A4: instrumento_clave | B4: fecha | C4: precio | D4: fuente_nombre | E4: carga | F4: día de la semana (1 = lunes) | G4: ¿día con operaciones? | I4: fecha | J4: instrumento_clave | K4: fecha del cierre usado | L4: precio usado | M4: ¿sin cierre ese día?
A5: DEMOACC | B5: 46275 | C5: 100.2 | D5: Semilla sintetica de demostracion 077 | E5: C-PRECIOS | F5: =WEEKDAY(B5,2) -> 4 | G5: =AND(F5<=5,COUNTIF(Entradas!$A$65:$A$178,B5)=0) -> TRUE | I5: 46275 | J5: DEMOACC | K5: =_xlfn.MAXIFS($B$5:$B$75,$A$5:$A$75,J5,$B$5:$B$75,"<="&I5) -> 46275 | L5: =SUMIFS($C$5:$C$75,$A$5:$A$75,J5,$B$5:$B$75,K5) -> 100.2 | M5: =IF(K5<I5,"sí","no") -> no
A6: DEMOACC | B6: 46276 | C6: 101.85 | D6: Semilla sintetica de demostracion 077 | E6: C-PRECIOS | F6: =WEEKDAY(B6,2) -> 5 | G6: =AND(F6<=5,COUNTIF(Entradas!$A$65:$A$178,B6)=0) -> TRUE | I6: 46275 | J6: DEMOETF | K6: =_xlfn.MAXIFS($B$5:$B$75,$A$5:$A$75,J6,$B$5:$B$75,"<="&I6) -> 46275 | L6: =SUMIFS($C$5:$C$75,$A$5:$A$75,J6,$B$5:$B$75,K6) -> 50.1 | M6: =IF(K6<I6,"sí","no") -> no
A7: DEMOACC | B7: 46279 | C7: 103.4 | D7: Semilla sintetica de demostracion 077 | E7: C-PRECIOS | F7: =WEEKDAY(B7,2) -> 1 | G7: =AND(F7<=5,COUNTIF(Entradas!$A$65:$A$178,B7)=0) -> TRUE | I7: 46275 | J7: DEMOFIB | K7: =_xlfn.MAXIFS($B$5:$B$75,$A$5:$A$75,J7,$B$5:$B$75,"<="&I7) -> 46275 | L7: =SUMIFS($C$5:$C$75,$A$5:$A$75,J7,$B$5:$B$75,K7) -> 24.8 | M7: =IF(K7<I7,"sí","no") -> no
A8: DEMOACC | B8: 46280 | C8: 104.75 | D8: Semilla sintetica de demostracion 077 | E8: C-PRECIOS | F8: =WEEKDAY(B8,2) -> 2 | G8: =AND(F8<=5,COUNTIF(Entradas!$A$65:$A$178,B8)=0) -> TRUE | I8: 46276 | J8: DEMOACC | K8: =_xlfn.MAXIFS($B$5:$B$75,$A$5:$A$75,J8,$B$5:$B$75,"<="&I8) -> 46276 | L8: =SUMIFS($C$5:$C$75,$A$5:$A$75,J8,$B$5:$B$75,K8) -> 101.85 | M8: =IF(K8<I8,"sí","no") -> no
A9: DEMOACC | B9: 46282 | C9: 102.1 | D9: Semilla sintetica de demostracion 077 | E9: C-PRECIOS | F9: =WEEKDAY(B9,2) -> 4 | G9: =AND(F9<=5,COUNTIF(Entradas!$A$65:$A$178,B9)=0) -> TRUE | I9: 46276 | J9: DEMOETF | K9: =_xlfn.MAXIFS($B$5:$B$75,$A$5:$A$75,J9,$B$5:$B$75,"<="&I9) -> 46276 | L9: =SUMIFS($C$5:$C$75,$A$5:$A$75,J9,$B$5:$B$75,K9) -> 50.62 | M9: =IF(K9<I9,"sí","no") -> no
A10: DEMOACC | B10: 46283 | C10: 98.65 | D10: Semilla sintetica de demostracion 077 | E10: C-PRECIOS | F10: =WEEKDAY(B10,2) -> 5 | G10: =AND(F10<=5,COUNTIF(Entradas!$A$65:$A$178,B10)=0) -> TRUE | I10: 46276 | J10: DEMOFIB | K10: =_xlfn.MAXIFS($B$5:$B$75,$A$5:$A$75,J10,$B$5:$B$75,"<="&I10) -> 46276 | L10: =SUMIFS($C$5:$C$75,$A$5:$A$75,J10,$B$5:$B$75,K10) -> 25.015 | M10: =IF(K10<I10,"sí","no") -> no
A11: DEMOACC | B11: 46286 | C11: 95.3 | D11: Semilla sintetica de demostracion 077 | E11: C-PRECIOS | F11: =WEEKDAY(B11,2) -> 1 | G11: =AND(F11<=5,COUNTIF(Entradas!$A$65:$A$178,B11)=0) -> TRUE | I11: 46277 | J11: DEMOACC | K11: =_xlfn.MAXIFS($B$5:$B$75,$A$5:$A$75,J11,$B$5:$B$75,"<="&I11) -> 46276 | L11: =SUMIFS($C$5:$C$75,$A$5:$A$75,J11,$B$5:$B$75,K11) -> 101.85 | M11: =IF(K11<I11,"sí","no") -> sí
A12: DEMOACC | B12: 46287 | C12: 92.15 | D12: Semilla sintetica de demostracion 077 | E12: C-PRECIOS | F12: =WEEKDAY(B12,2) -> 2 | G12: =AND(F12<=5,COUNTIF(Entradas!$A$65:$A$178,B12)=0) -> TRUE | I12: 46277 | J12: DEMOETF | K12: =_xlfn.MAXIFS($B$5:$B$75,$A$5:$A$75,J12,$B$5:$B$75,"<="&I12) -> 46276 | L12: =SUMIFS($C$5:$C$75,$A$5:$A$75,J12,$B$5:$B$75,K12) -> 50.62 | M12: =IF(K12<I12,"sí","no") -> sí
A13: DEMOACC | B13: 46288 | C13: 90.425 | D13: Semilla sintetica de demostracion 077 | E13: C-PRECIOS | F13: =WEEKDAY(B13,2) -> 3 | G13: =AND(F13<=5,COUNTIF(Entradas!$A$65:$A$178,B13)=0) -> TRUE | I13: 46277 | J13: DEMOFIB | K13: =_xlfn.MAXIFS($B$5:$B$75,$A$5:$A$75,J13,$B$5:$B$75,"<="&I13) -> 46276 | L13: =SUMIFS($C$5:$C$75,$A$5:$A$75,J13,$B$5:$B$75,K13) -> 25.015 | M13: =IF(K13<I13,"sí","no") -> sí
A14: DEMOACC | B14: 46289 | C14: 92.8 | D14: Semilla sintetica de demostracion 077 | E14: C-PRECIOS | F14: =WEEKDAY(B14,2) -> 4 | G14: =AND(F14<=5,COUNTIF(Entradas!$A$65:$A$178,B14)=0) -> TRUE | I14: 46278 | J14: DEMOACC | K14: =_xlfn.MAXIFS($B$5:$B$75,$A$5:$A$75,J14,$B$5:$B$75,"<="&I14) -> 46276 | L14: =SUMIFS($C$5:$C$75,$A$5:$A$75,J14,$B$5:$B$75,K14) -> 101.85 | M14: =IF(K14<I14,"sí","no") -> sí
A15: DEMOACC | B15: 46290 | C15: 96.15 | D15: Semilla sintetica de demostracion 077 | E15: C-PRECIOS | F15: =WEEKDAY(B15,2) -> 5 | G15: =AND(F15<=5,COUNTIF(Entradas!$A$65:$A$178,B15)=0) -> TRUE | I15: 46278 | J15: DEMOETF | K15: =_xlfn.MAXIFS($B$5:$B$75,$A$5:$A$75,J15,$B$5:$B$75,"<="&I15) -> 46276 | L15: =SUMIFS($C$5:$C$75,$A$5:$A$75,J15,$B$5:$B$75,K15) -> 50.62 | M15: =IF(K15<I15,"sí","no") -> sí
A16: DEMOACC | B16: 46293 | C16: 99.7 | D16: Semilla sintetica de demostracion 077 | E16: C-PRECIOS | F16: =WEEKDAY(B16,2) -> 1 | G16: =AND(F16<=5,COUNTIF(Entradas!$A$65:$A$178,B16)=0) -> TRUE | I16: 46278 | J16: DEMOFIB | K16: =_xlfn.MAXIFS($B$5:$B$75,$A$5:$A$75,J16,$B$5:$B$75,"<="&I16) -> 46276 | L16: =SUMIFS($C$5:$C$75,$A$5:$A$75,J16,$B$5:$B$75,K16) -> 25.015 | M16: =IF(K16<I16,"sí","no") -> sí
... A75: DEMOFIB | B75: 46309 | C75: 25.6225 | D75: Semilla sintetica de demostracion 077 | E75: C-PRECIOS | F75: =WEEKDAY(B75,2) -> 3 | G75: =AND(F75<=5,COUNTIF(Entradas!$A$65:$A$178,B75)=0) -> TRUE | I75: 46298 | J75: DEMOETF | K75: =_xlfn.MAXIFS($B$5:$B$75,$A$5:$A$75,J75,$B$5:$B$75,"<="&I75) -> 46297 | L75: =SUMIFS($C$5:$C$75,$A$5:$A$75,J75,$B$5:$B$75,K75) -> 50.58 | M75: =IF(K75<I75,"sí","no") -> sí
I76: 46298 | J76: DEMOFIB | K76: =_xlfn.MAXIFS($B$5:$B$75,$A$5:$A$75,J76,$B$5:$B$75,"<="&I76) -> 46297 | L76: =SUMIFS($C$5:$C$75,$A$5:$A$75,J76,$B$5:$B$75,K76) -> 24.6125 | M76: =IF(K76<I76,"sí","no") -> sí
I77: 46299 | J77: DEMOACC | K77: =_xlfn.MAXIFS($B$5:$B$75,$A$5:$A$75,J77,$B$5:$B$75,"<="&I77) -> 46297 | L77: =SUMIFS($C$5:$C$75,$A$5:$A$75,J77,$B$5:$B$75,K77) -> 103.9 | M77: =IF(K77<I77,"sí","no") -> sí
I78: 46299 | J78: DEMOETF | K78: =_xlfn.MAXIFS($B$5:$B$75,$A$5:$A$75,J78,$B$5:$B$75,"<="&I78) -> 46297 | L78: =SUMIFS($C$5:$C$75,$A$5:$A$75,J78,$B$5:$B$75,K78) -> 50.58 | M78: =IF(K78<I78,"sí","no") -> sí
I79: 46299 | J79: DEMOFIB | K79: =_xlfn.MAXIFS($B$5:$B$75,$A$5:$A$75,J79,$B$5:$B$75,"<="&I79) -> 46297 | L79: =SUMIFS($C$5:$C$75,$A$5:$A$75,J79,$B$5:$B$75,K79) -> 24.6125 | M79: =IF(K79<I79,"sí","no") -> sí
I80: 46300 | J80: DEMOACC | K80: =_xlfn.MAXIFS($B$5:$B$75,$A$5:$A$75,J80,$B$5:$B$75,"<="&I80) -> 46300 | L80: =SUMIFS($C$5:$C$75,$A$5:$A$75,J80,$B$5:$B$75,K80) -> 101.65 | M80: =IF(K80<I80,"sí","no") -> no
I81: 46300 | J81: DEMOETF | K81: =_xlfn.MAXIFS($B$5:$B$75,$A$5:$A$75,J81,$B$5:$B$75,"<="&I81) -> 46300 | L81: =SUMIFS($C$5:$C$75,$A$5:$A$75,J81,$B$5:$B$75,K81) -> 49.83 | M81: =IF(K81<I81,"sí","no") -> no
I82: 46300 | J82: DEMOFIB | K82: =_xlfn.MAXIFS($B$5:$B$75,$A$5:$A$75,J82,$B$5:$B$75,"<="&I82) -> 46300 | L82: =SUMIFS($C$5:$C$75,$A$5:$A$75,J82,$B$5:$B$75,K82) -> 24.37 | M82: =IF(K82<I82,"sí","no") -> no
I83: 46301 | J83: DEMOACC | K83: =_xlfn.MAXIFS($B$5:$B$75,$A$5:$A$75,J83,$B$5:$B$75,"<="&I83) -> 46301 | L83: =SUMIFS($C$5:$C$75,$A$5:$A$75,J83,$B$5:$B$75,K83) -> 102.8 | M83: =IF(K83<I83,"sí","no") -> no
I84: 46301 | J84: DEMOETF | K84: =_xlfn.MAXIFS($B$5:$B$75,$A$5:$A$75,J84,$B$5:$B$75,"<="&I84) -> 46301 | L84: =SUMIFS($C$5:$C$75,$A$5:$A$75,J84,$B$5:$B$75,K84) -> 50.24 | M84: =IF(K84<I84,"sí","no") -> no
I85: 46301 | J85: DEMOFIB | K85: =_xlfn.MAXIFS($B$5:$B$75,$A$5:$A$75,J85,$B$5:$B$75,"<="&I85) -> 46301 | L85: =SUMIFS($C$5:$C$75,$A$5:$A$75,J85,$B$5:$B$75,K85) -> 24.515 | M85: =IF(K85<I85,"sí","no") -> no
I86: 46302 | J86: DEMOACC | K86: =_xlfn.MAXIFS($B$5:$B$75,$A$5:$A$75,J86,$B$5:$B$75,"<="&I86) -> 46302 | L86: =SUMIFS($C$5:$C$75,$A$5:$A$75,J86,$B$5:$B$75,K86) -> 104.95 | M86: =IF(K86<I86,"sí","no") -> no
I87: 46302 | J87: DEMOETF | K87: =_xlfn.MAXIFS($B$5:$B$75,$A$5:$A$75,J87,$B$5:$B$75,"<="&I87) -> 46302 | L87: =SUMIFS($C$5:$C$75,$A$5:$A$75,J87,$B$5:$B$75,K87) -> 50.96 | M87: =IF(K87<I87,"sí","no") -> no
... I109: 46309 | J109: DEMOFIB | K109: =_xlfn.MAXIFS($B$5:$B$75,$A$5:$A$75,J109,$B$5:$B$75,"<="&I109) -> 46309 | L109: =SUMIFS($C$5:$C$75,$A$5:$A$75,J109,$B$5:$B$75,K109) -> 25.6225 | M109: =IF(K109<I109,"sí","no") -> no

Sheet Tasas
A1: Tasas de las subastas primarias de CETES (RF-30; tasa_referencia de 4.4)
A2: Fuente: Banco de México, SIE, cuadro CF107 (https://www.banxico.org.mx). Series de tasa SF43936, SF43939, SF43942, SF43945 y SF349785; de plazo SF43935, SF43938, SF43941, SF43944 y SF349778. Consulta: 15/10/2026. Fecha = colocación (D-02, R-14).
A4: plazo_nominal | B4: fecha_colocacion | C4: valor | D4: unidad | E4: plazo_efectivo | F4: fuente_nombre | G4: carga | H4: serie de la tasa | I4: serie del plazo | J4: fuentes que coinciden (15/10/2026) | K4: valuaciones de CETES que la usan
A5: 28 | B5: 46261 | C5: 6.13 | D5: por ciento anual | E5: 28 | F5: Banco de México | G5: C-TASAS | H5: SF43936 | I5: SF43935 | J5: consultaSerieGrafica.do (JSON publico, 15 oct) | K5: =COUNTIFS(CETES!$Y$5:$Y$95,B5,CETES!$W$5:$W$95,A5)+COUNTIFS(CETES!$Z$5:$Z$95,B5,CETES!$X$5:$X$95,A5,CETES!$AC$5:$AC$95,"interpolación") -> 0
A6: 91 | B6: 46261 | C6: 6.6 | D6: por ciento anual | E6: 91 | F6: Banco de México | G6: C-TASAS | H6: SF43939 | I6: SF43938 | J6: consultaSerieGrafica.do (JSON publico, 15 oct) | K6: =COUNTIFS(CETES!$Y$5:$Y$95,B6,CETES!$W$5:$W$95,A6)+COUNTIFS(CETES!$Z$5:$Z$95,B6,CETES!$X$5:$X$95,A6,CETES!$AC$5:$AC$95,"interpolación") -> 0
A7: 182 | B7: 46261 | C7: 6.72 | D7: por ciento anual | E7: 175 | F7: Banco de México | G7: C-TASAS | H7: SF43942 | I7: SF43941 | J7: consultaSerieGrafica.do (JSON publico, 15 oct) | K7: =COUNTIFS(CETES!$Y$5:$Y$95,B7,CETES!$W$5:$W$95,A7)+COUNTIFS(CETES!$Z$5:$Z$95,B7,CETES!$X$5:$X$95,A7,CETES!$AC$5:$AC$95,"interpolación") -> 0
A8: 728 | B8: 46261 | C8: 7.87 | D8: por ciento anual | E8: 707 | F8: Banco de México | G8: C-TASAS | H8: SF349785 | I8: SF349778 | J8: consultaSerieGrafica.do (JSON publico, 15 oct) | K8: =COUNTIFS(CETES!$Y$5:$Y$95,B8,CETES!$W$5:$W$95,A8)+COUNTIFS(CETES!$Z$5:$Z$95,B8,CETES!$X$5:$X$95,A8,CETES!$AC$5:$AC$95,"interpolación") -> 0
A9: 28 | B9: 46268 | C9: 6.49 | D9: por ciento anual | E9: 28 | F9: Banco de México | G9: C-TASAS | H9: SF43936 | I9: SF43935 | J9: consultaSerieGrafica.do (JSON publico, 15 oct) | K9: =COUNTIFS(CETES!$Y$5:$Y$95,B9,CETES!$W$5:$W$95,A9)+COUNTIFS(CETES!$Z$5:$Z$95,B9,CETES!$X$5:$X$95,A9,CETES!$AC$5:$AC$95,"interpolación") -> 0
A10: 91 | B10: 46268 | C10: 6.54 | D10: por ciento anual | E10: 91 | F10: Banco de México | G10: C-TASAS | H10: SF43939 | I10: SF43938 | J10: consultaSerieGrafica.do (JSON publico, 15 oct) | K10: =COUNTIFS(CETES!$Y$5:$Y$95,B10,CETES!$W$5:$W$95,A10)+COUNTIFS(CETES!$Z$5:$Z$95,B10,CETES!$X$5:$X$95,A10,CETES!$AC$5:$AC$95,"interpolación") -> 0
A11: 182 | B11: 46268 | C11: 6.69 | D11: por ciento anual | E11: 182 | F11: Banco de México | G11: C-TASAS | H11: SF43942 | I11: SF43941 | J11: consultaSerieGrafica.do (JSON publico, 15 oct) | K11: =COUNTIFS(CETES!$Y$5:$Y$95,B11,CETES!$W$5:$W$95,A11)+COUNTIFS(CETES!$Z$5:$Z$95,B11,CETES!$X$5:$X$95,A11,CETES!$AC$5:$AC$95,"interpolación") -> 0
A12: 364 | B12: 46268 | C12: 7 | D12: por ciento anual | E12: 350 | F12: Banco de México | G12: C-TASAS | H12: SF43945 | I12: SF43944 | J12: consultaSerieGrafica.do (JSON publico, 15 oct) | K12: =COUNTIFS(CETES!$Y$5:$Y$95,B12,CETES!$W$5:$W$95,A12)+COUNTIFS(CETES!$Z$5:$Z$95,B12,CETES!$X$5:$X$95,A12,CETES!$AC$5:$AC$95,"interpolación") -> 0
A13: 28 | B13: 46275 | C13: 6.25 | D13: por ciento anual | E13: 28 | F13: Banco de México | G13: C-TASAS | H13: SF43936 | I13: SF43935 | J13: consultaSerieGrafica.do (JSON publico, 15 oct) | K13: =COUNTIFS(CETES!$Y$5:$Y$95,B13,CETES!$W$5:$W$95,A13)+COUNTIFS(CETES!$Z$5:$Z$95,B13,CETES!$X$5:$X$95,A13,CETES!$AC$5:$AC$95,"interpolación") -> 7
A14: 91 | B14: 46275 | C14: 6.56 | D14: por ciento anual | E14: 91 | F14: Banco de México | G14: C-TASAS | H14: SF43939 | I14: SF43938 | J14: consultaSerieGrafica.do (JSON publico, 15 oct) | K14: =COUNTIFS(CETES!$Y$5:$Y$95,B14,CETES!$W$5:$W$95,A14)+COUNTIFS(CETES!$Z$5:$Z$95,B14,CETES!$X$5:$X$95,A14,CETES!$AC$5:$AC$95,"interpolación") -> 0
A15: 182 | B15: 46275 | C15: 6.78 | D15: por ciento anual | E15: 175 | F15: Banco de México | G15: C-TASAS | H15: SF43942 | I15: SF43941 | J15: consultaSerieGrafica.do (JSON publico, 15 oct) | K15: =COUNTIFS(CETES!$Y$5:$Y$95,B15,CETES!$W$5:$W$95,A15)+COUNTIFS(CETES!$Z$5:$Z$95,B15,CETES!$X$5:$X$95,A15,CETES!$AC$5:$AC$95,"interpolación") -> 0
A16: 728 | B16: 46275 | C16: 7.94 | D16: por ciento anual | E16: 693 | F16: Banco de México | G16: C-TASAS | H16: SF349785 | I16: SF349778 | J16: consultaSerieGrafica.do (JSON publico, 15 oct) | K16: =COUNTIFS(CETES!$Y$5:$Y$95,B16,CETES!$W$5:$W$95,A16)+COUNTIFS(CETES!$Z$5:$Z$95,B16,CETES!$X$5:$X$95,A16,CETES!$AC$5:$AC$95,"interpolación") -> 0
... A36: 364 | B36: 46310 | C36: 7.11 | D36: por ciento anual | E36: 364 | F36: Banco de México | G36: C-TASAS | H36: SF43945 | I36: SF43944 | J36: cf107_15oct.html (pagina publica, 15 oct) | consultaSerieGrafica.do (JSON publico, 15 oct) | K36: =COUNTIFS(CETES!$Y$5:$Y$95,B36,CETES!$W$5:$W$95,A36)+COUNTIFS(CETES!$Z$5:$Z$95,B36,CETES!$X$5:$X$95,A36,CETES!$AC$5:$AC$95,"interpolación") -> 0

Sheet CETES
A1: Valuación de CETES antes del vencimiento (RF-26b)
A2: Para cada plazo nominal rige la última colocación con fecha igual o anterior a la de valuación (F–J). Se interpola linealmente por plazo efectivo entre los dos nodos que encierran d; fuera del rango, la tasa del extremo. r sin redondear; P = ROUND(VN / (1 + r/100 × d/360); 7), mitad alejándose de cero.
F3: Fecha de colocación vigente, por plazo nominal (días) | K3: Tasa vigente (% anual) | P3: Plazo efectivo (días)
A4: fecha | B4: instrumento_clave | C4: vencimiento | D4: valor nominal | E4: d (días por vencer) | F4: 28 | G4: 91 | H4: 182 | I4: 364 | J4: 728 | K4: 28 | L4: 91 | M4: 182 | N4: 364 | O4: 728 | P4: 28 | Q4: 91 | R4: 182 | S4: 364 | T4: 728 | U4: plazo efectivo inferior | V4: plazo efectivo superior | W4: plazo nominal inferior | X4: plazo nominal superior | Y4: colocación inferior | Z4: colocación superior | AA4: tasa inferior | AB4: tasa superior | AC4: caso | AD4: r (% anual, sin redondear) | AE4: P sin redondear | AF4: P (7 decimales) | AG4: llave
A5: 46275 | B5: BI261008 | C5: =INDEX(Entradas!$F$40:$F$46,MATCH(B5,Entradas!$A$40:$A$46,0)) -> 46303 | D5: =INDEX(Entradas!$G$40:$G$46,MATCH(B5,Entradas!$A$40:$A$46,0)) -> 10 | E5: =C5-A5 -> 28 | F5: =_xlfn.MAXIFS(Tasas!$B$5:$B$36,Tasas!$A$5:$A$36,F$4,Tasas!$B$5:$B$36,"<="&$A5) -> 46275 | G5: =_xlfn.MAXIFS(Tasas!$B$5:$B$36,Tasas!$A$5:$A$36,G$4,Tasas!$B$5:$B$36,"<="&$A5) -> 46275 | H5: =_xlfn.MAXIFS(Tasas!$B$5:$B$36,Tasas!$A$5:$A$36,H$4,Tasas!$B$5:$B$36,"<="&$A5) -> 46275 | I5: =_xlfn.MAXIFS(Tasas!$B$5:$B$36,Tasas!$A$5:$A$36,I$4,Tasas!$B$5:$B$36,"<="&$A5) -> 46268 | J5: =_xlfn.MAXIFS(Tasas!$B$5:$B$36,Tasas!$A$5:$A$36,J$4,Tasas!$B$5:$B$36,"<="&$A5) -> 46275 | K5: =SUMIFS(Tasas!$C$5:$C$36,Tasas!$A$5:$A$36,K$4,Tasas!$B$5:$B$36,F5) -> 6.25 | L5: =SUMIFS(Tasas!$C$5:$C$36,Tasas!$A$5:$A$36,L$4,Tasas!$B$5:$B$36,G5) -> 6.56 | M5: =SUMIFS(Tasas!$C$5:$C$36,Tasas!$A$5:$A$36,M$4,Tasas!$B$5:$B$36,H5) -> 6.78 | N5: =SUMIFS(Tasas!$C$5:$C$36,Tasas!$A$5:$A$36,N$4,Tasas!$B$5:$B$36,I5) -> 7 | O5: =SUMIFS(Tasas!$C$5:$C$36,Tasas!$A$5:$A$36,O$4,Tasas!$B$5:$B$36,J5) -> 7.94 | P5: =SUMIFS(Tasas!$E$5:$E$36,Tasas!$A$5:$A$36,P$4,Tasas!$B$5:$B$36,F5) -> 28 | Q5: =SUMIFS(Tasas!$E$5:$E$36,Tasas!$A$5:$A$36,Q$4,Tasas!$B$5:$B$36,G5) -> 91 | R5: =SUMIFS(Tasas!$E$5:$E$36,Tasas!$A$5:$A$36,R$4,Tasas!$B$5:$B$36,H5) -> 175 | S5: =SUMIFS(Tasas!$E$5:$E$36,Tasas!$A$5:$A$36,S$4,Tasas!$B$5:$B$36,I5) -> 350 | T5: =SUMIFS(Tasas!$E$5:$E$36,Tasas!$A$5:$A$36,T$4,Tasas!$B$5:$B$36,J5) -> 693 | U5: =IF($E5<=MIN($P5:$T5),MIN($P5:$T5),_xlfn.MAXIFS($P5:$T5,$P5:$T5,"<="&$E5)) -> 28 | V5: =IF($E5>=MAX($P5:$T5),MAX($P5:$T5),_xlfn.MINIFS($P5:$T5,$P5:$T5,">="&$E5)) -> 28 | W5: =INDEX($P$4:$T$4,MATCH(U5,$P5:$T5,0)) -> 28 | X5: =INDEX($P$4:$T$4,MATCH(V5,$P5:$T5,0)) -> 28 | Y5: =INDEX($F5:$J5,MATCH(U5,$P5:$T5,0)) -> 46275 | Z5: =INDEX($F5:$J5,MATCH(V5,$P5:$T5,0)) -> 46275 | AA5: =INDEX($K5:$O5,MATCH(U5,$P5:$T5,0)) -> 6.25 | AB5: =INDEX($K5:$O5,MATCH(V5,$P5:$T5,0)) -> 6.25 | AC5: =IF(E5<MIN($P5:$T5),"extremo inferior",IF(E5>MAX($P5:$T5),"extremo superior",IF(U5=V5,"nodo","interpolación"))) -> nodo | AD5: =IF(U5=V5,AA5,AA5+(AB5-AA5)*(E5-U5)/(V5-U5)) -> 6.25 | AE5: =D5/(1+AD5/100*E5/360) -> 9.951624 | AF5: =ROUND(AE5,7) -> 9.951624 | AG5: =A5&"|"&B5 -> 46275|BI261008
A6: 46276 | B6: BI261008 | C6: =INDEX(Entradas!$F$40:$F$46,MATCH(B6,Entradas!$A$40:$A$46,0)) -> 46303 | D6: =INDEX(Entradas!$G$40:$G$46,MATCH(B6,Entradas!$A$40:$A$46,0)) -> 10 | E6: =C6-A6 -> 27 | F6: =_xlfn.MAXIFS(Tasas!$B$5:$B$36,Tasas!$A$5:$A$36,F$4,Tasas!$B$5:$B$36,"<="&$A6) -> 46275 | G6: =_xlfn.MAXIFS(Tasas!$B$5:$B$36,Tasas!$A$5:$A$36,G$4,Tasas!$B$5:$B$36,"<="&$A6) -> 46275 | H6: =_xlfn.MAXIFS(Tasas!$B$5:$B$36,Tasas!$A$5:$A$36,H$4,Tasas!$B$5:$B$36,"<="&$A6) -> 46275 | I6: =_xlfn.MAXIFS(Tasas!$B$5:$B$36,Tasas!$A$5:$A$36,I$4,Tasas!$B$5:$B$36,"<="&$A6) -> 46268 | J6: =_xlfn.MAXIFS(Tasas!$B$5:$B$36,Tasas!$A$5:$A$36,J$4,Tasas!$B$5:$B$36,"<="&$A6) -> 46275 | K6: =SUMIFS(Tasas!$C$5:$C$36,Tasas!$A$5:$A$36,K$4,Tasas!$B$5:$B$36,F6) -> 6.25 | L6: =SUMIFS(Tasas!$C$5:$C$36,Tasas!$A$5:$A$36,L$4,Tasas!$B$5:$B$36,G6) -> 6.56 | M6: =SUMIFS(Tasas!$C$5:$C$36,Tasas!$A$5:$A$36,M$4,Tasas!$B$5:$B$36,H6) -> 6.78 | N6: =SUMIFS(Tasas!$C$5:$C$36,Tasas!$A$5:$A$36,N$4,Tasas!$B$5:$B$36,I6) -> 7 | O6: =SUMIFS(Tasas!$C$5:$C$36,Tasas!$A$5:$A$36,O$4,Tasas!$B$5:$B$36,J6) -> 7.94 | P6: =SUMIFS(Tasas!$E$5:$E$36,Tasas!$A$5:$A$36,P$4,Tasas!$B$5:$B$36,F6) -> 28 | Q6: =SUMIFS(Tasas!$E$5:$E$36,Tasas!$A$5:$A$36,Q$4,Tasas!$B$5:$B$36,G6) -> 91 | R6: =SUMIFS(Tasas!$E$5:$E$36,Tasas!$A$5:$A$36,R$4,Tasas!$B$5:$B$36,H6) -> 175 | S6: =SUMIFS(Tasas!$E$5:$E$36,Tasas!$A$5:$A$36,S$4,Tasas!$B$5:$B$36,I6) -> 350 | T6: =SUMIFS(Tasas!$E$5:$E$36,Tasas!$A$5:$A$36,T$4,Tasas!$B$5:$B$36,J6) -> 693 | U6: =IF($E6<=MIN($P6:$T6),MIN($P6:$T6),_xlfn.MAXIFS($P6:$T6,$P6:$T6,"<="&$E6)) -> 28 | V6: =IF($E6>=MAX($P6:$T6),MAX($P6:$T6),_xlfn.MINIFS($P6:$T6,$P6:$T6,">="&$E6)) -> 28 | W6: =INDEX($P$4:$T$4,MATCH(U6,$P6:$T6,0)) -> 28 | X6: =INDEX($P$4:$T$4,MATCH(V6,$P6:$T6,0)) -> 28 | Y6: =INDEX($F6:$J6,MATCH(U6,$P6:$T6,0)) -> 46275 | Z6: =INDEX($F6:$J6,MATCH(V6,$P6:$T6,0)) -> 46275 | AA6: =INDEX($K6:$O6,MATCH(U6,$P6:$T6,0)) -> 6.25 | AB6: =INDEX($K6:$O6,MATCH(V6,$P6:$T6,0)) -> 6.25 | AC6: =IF(E6<MIN($P6:$T6),"extremo inferior",IF(E6>MAX($P6:$T6),"extremo superior",IF(U6=V6,"nodo","interpolación"))) -> extremo inferior | AD6: =IF(U6=V6,AA6,AA6+(AB6-AA6)*(E6-U6)/(V6-U6)) -> 6.25 | AE6: =D6/(1+AD6/100*E6/360) -> 9.9533437 | AF6: =ROUND(AE6,7) -> 9.9533437 | AG6: =A6&"|"&B6 -> 46276|BI261008
A7: 46277 | B7: BI261008 | C7: =INDEX(Entradas!$F$40:$F$46,MATCH(B7,Entradas!$A$40:$A$46,0)) -> 46303 | D7: =INDEX(Entradas!$G$40:$G$46,MATCH(B7,Entradas!$A$40:$A$46,0)) -> 10 | E7: =C7-A7 -> 26 | F7: =_xlfn.MAXIFS(Tasas!$B$5:$B$36,Tasas!$A$5:$A$36,F$4,Tasas!$B$5:$B$36,"<="&$A7) -> 46275 | G7: =_xlfn.MAXIFS(Tasas!$B$5:$B$36,Tasas!$A$5:$A$36,G$4,Tasas!$B$5:$B$36,"<="&$A7) -> 46275 | H7: =_xlfn.MAXIFS(Tasas!$B$5:$B$36,Tasas!$A$5:$A$36,H$4,Tasas!$B$5:$B$36,"<="&$A7) -> 46275 | I7: =_xlfn.MAXIFS(Tasas!$B$5:$B$36,Tasas!$A$5:$A$36,I$4,Tasas!$B$5:$B$36,"<="&$A7) -> 46268 | J7: =_xlfn.MAXIFS(Tasas!$B$5:$B$36,Tasas!$A$5:$A$36,J$4,Tasas!$B$5:$B$36,"<="&$A7) -> 46275 | K7: =SUMIFS(Tasas!$C$5:$C$36,Tasas!$A$5:$A$36,K$4,Tasas!$B$5:$B$36,F7) -> 6.25 | L7: =SUMIFS(Tasas!$C$5:$C$36,Tasas!$A$5:$A$36,L$4,Tasas!$B$5:$B$36,G7) -> 6.56 | M7: =SUMIFS(Tasas!$C$5:$C$36,Tasas!$A$5:$A$36,M$4,Tasas!$B$5:$B$36,H7) -> 6.78 | N7: =SUMIFS(Tasas!$C$5:$C$36,Tasas!$A$5:$A$36,N$4,Tasas!$B$5:$B$36,I7) -> 7 | O7: =SUMIFS(Tasas!$C$5:$C$36,Tasas!$A$5:$A$36,O$4,Tasas!$B$5:$B$36,J7) -> 7.94 | P7: =SUMIFS(Tasas!$E$5:$E$36,Tasas!$A$5:$A$36,P$4,Tasas!$B$5:$B$36,F7) -> 28 | Q7: =SUMIFS(Tasas!$E$5:$E$36,Tasas!$A$5:$A$36,Q$4,Tasas!$B$5:$B$36,G7) -> 91 | R7: =SUMIFS(Tasas!$E$5:$E$36,Tasas!$A$5:$A$36,R$4,Tasas!$B$5:$B$36,H7) -> 175 | S7: =SUMIFS(Tasas!$E$5:$E$36,Tasas!$A$5:$A$36,S$4,Tasas!$B$5:$B$36,I7) -> 350 | T7: =SUMIFS(Tasas!$E$5:$E$36,Tasas!$A$5:$A$36,T$4,Tasas!$B$5:$B$36,J7) -> 693 | U7: =IF($E7<=MIN($P7:$T7),MIN($P7:$T7),_xlfn.MAXIFS($P7:$T7,$P7:$T7,"<="&$E7)) -> 28 | V7: =IF($E7>=MAX($P7:$T7),MAX($P7:$T7),_xlfn.MINIFS($P7:$T7,$P7:$T7,">="&$E7)) -> 28 | W7: =INDEX($P$4:$T$4,MATCH(U7,$P7:$T7,0)) -> 28 | X7: =INDEX($P$4:$T$4,MATCH(V7,$P7:$T7,0)) -> 28 | Y7: =INDEX($F7:$J7,MATCH(U7,$P7:$T7,0)) -> 46275 | Z7: =INDEX($F7:$J7,MATCH(V7,$P7:$T7,0)) -> 46275 | AA7: =INDEX($K7:$O7,MATCH(U7,$P7:$T7,0)) -> 6.25 | AB7: =INDEX($K7:$O7,MATCH(V7,$P7:$T7,0)) -> 6.25 | AC7: =IF(E7<MIN($P7:$T7),"extremo inferior",IF(E7>MAX($P7:$T7),"extremo superior",IF(U7=V7,"nodo","interpolación"))) -> extremo inferior | AD7: =IF(U7=V7,AA7,AA7+(AB7-AA7)*(E7-U7)/(V7-U7)) -> 6.25 | AE7: =D7/(1+AD7/100*E7/360) -> 9.9550639 | AF7: =ROUND(AE7,7) -> 9.9550639 | AG7: =A7&"|"&B7 -> 46277|BI261008
A8: 46278 | B8: BI261008 | C8: =INDEX(Entradas!$F$40:$F$46,MATCH(B8,Entradas!$A$40:$A$46,0)) -> 46303 | D8: =INDEX(Entradas!$G$40:$G$46,MATCH(B8,Entradas!$A$40:$A$46,0)) -> 10 | E8: =C8-A8 -> 25 | F8: =_xlfn.MAXIFS(Tasas!$B$5:$B$36,Tasas!$A$5:$A$36,F$4,Tasas!$B$5:$B$36,"<="&$A8) -> 46275 | G8: =_xlfn.MAXIFS(Tasas!$B$5:$B$36,Tasas!$A$5:$A$36,G$4,Tasas!$B$5:$B$36,"<="&$A8) -> 46275 | H8: =_xlfn.MAXIFS(Tasas!$B$5:$B$36,Tasas!$A$5:$A$36,H$4,Tasas!$B$5:$B$36,"<="&$A8) -> 46275 | I8: =_xlfn.MAXIFS(Tasas!$B$5:$B$36,Tasas!$A$5:$A$36,I$4,Tasas!$B$5:$B$36,"<="&$A8) -> 46268 | J8: =_xlfn.MAXIFS(Tasas!$B$5:$B$36,Tasas!$A$5:$A$36,J$4,Tasas!$B$5:$B$36,"<="&$A8) -> 46275 | K8: =SUMIFS(Tasas!$C$5:$C$36,Tasas!$A$5:$A$36,K$4,Tasas!$B$5:$B$36,F8) -> 6.25 | L8: =SUMIFS(Tasas!$C$5:$C$36,Tasas!$A$5:$A$36,L$4,Tasas!$B$5:$B$36,G8) -> 6.56 | M8: =SUMIFS(Tasas!$C$5:$C$36,Tasas!$A$5:$A$36,M$4,Tasas!$B$5:$B$36,H8) -> 6.78 | N8: =SUMIFS(Tasas!$C$5:$C$36,Tasas!$A$5:$A$36,N$4,Tasas!$B$5:$B$36,I8) -> 7 | O8: =SUMIFS(Tasas!$C$5:$C$36,Tasas!$A$5:$A$36,O$4,Tasas!$B$5:$B$36,J8) -> 7.94 | P8: =SUMIFS(Tasas!$E$5:$E$36,Tasas!$A$5:$A$36,P$4,Tasas!$B$5:$B$36,F8) -> 28 | Q8: =SUMIFS(Tasas!$E$5:$E$36,Tasas!$A$5:$A$36,Q$4,Tasas!$B$5:$B$36,G8) -> 91 | R8: =SUMIFS(Tasas!$E$5:$E$36,Tasas!$A$5:$A$36,R$4,Tasas!$B$5:$B$36,H8) -> 175 | S8: =SUMIFS(Tasas!$E$5:$E$36,Tasas!$A$5:$A$36,S$4,Tasas!$B$5:$B$36,I8) -> 350 | T8: =SUMIFS(Tasas!$E$5:$E$36,Tasas!$A$5:$A$36,T$4,Tasas!$B$5:$B$36,J8) -> 693 | U8: =IF($E8<=MIN($P8:$T8),MIN($P8:$T8),_xlfn.MAXIFS($P8:$T8,$P8:$T8,"<="&$E8)) -> 28 | V8: =IF($E8>=MAX($P8:$T8),MAX($P8:$T8),_xlfn.MINIFS($P8:$T8,$P8:$T8,">="&$E8)) -> 28 | W8: =INDEX($P$4:$T$4,MATCH(U8,$P8:$T8,0)) -> 28 | X8: =INDEX($P$4:$T$4,MATCH(V8,$P8:$T8,0)) -> 28 | Y8: =INDEX($F8:$J8,MATCH(U8,$P8:$T8,0)) -> 46275 | Z8: =INDEX($F8:$J8,MATCH(V8,$P8:$T8,0)) -> 46275 | AA8: =INDEX($K8:$O8,MATCH(U8,$P8:$T8,0)) -> 6.25 | AB8: =INDEX($K8:$O8,MATCH(V8,$P8:$T8,0)) -> 6.25 | AC8: =IF(E8<MIN($P8:$T8),"extremo inferior",IF(E8>MAX($P8:$T8),"extremo superior",IF(U8=V8,"nodo","interpolación"))) -> extremo inferior | AD8: =IF(U8=V8,AA8,AA8+(AB8-AA8)*(E8-U8)/(V8-U8)) -> 6.25 | AE8: =D8/(1+AD8/100*E8/360) -> 9.9567848 | AF8: =ROUND(AE8,7) -> 9.9567848 | AG8: =A8&"|"&B8 -> 46278|BI261008
A9: 46279 | B9: BI261008 | C9: =INDEX(Entradas!$F$40:$F$46,MATCH(B9,Entradas!$A$40:$A$46,0)) -> 46303 | D9: =INDEX(Entradas!$G$40:$G$46,MATCH(B9,Entradas!$A$40:$A$46,0)) -> 10 | E9: =C9-A9 -> 24 | F9: =_xlfn.MAXIFS(Tasas!$B$5:$B$36,Tasas!$A$5:$A$36,F$4,Tasas!$B$5:$B$36,"<="&$A9) -> 46275 | G9: =_xlfn.MAXIFS(Tasas!$B$5:$B$36,Tasas!$A$5:$A$36,G$4,Tasas!$B$5:$B$36,"<="&$A9) -> 46275 | H9: =_xlfn.MAXIFS(Tasas!$B$5:$B$36,Tasas!$A$5:$A$36,H$4,Tasas!$B$5:$B$36,"<="&$A9) -> 46275 | I9: =_xlfn.MAXIFS(Tasas!$B$5:$B$36,Tasas!$A$5:$A$36,I$4,Tasas!$B$5:$B$36,"<="&$A9) -> 46268 | J9: =_xlfn.MAXIFS(Tasas!$B$5:$B$36,Tasas!$A$5:$A$36,J$4,Tasas!$B$5:$B$36,"<="&$A9) -> 46275 | K9: =SUMIFS(Tasas!$C$5:$C$36,Tasas!$A$5:$A$36,K$4,Tasas!$B$5:$B$36,F9) -> 6.25 | L9: =SUMIFS(Tasas!$C$5:$C$36,Tasas!$A$5:$A$36,L$4,Tasas!$B$5:$B$36,G9) -> 6.56 | M9: =SUMIFS(Tasas!$C$5:$C$36,Tasas!$A$5:$A$36,M$4,Tasas!$B$5:$B$36,H9) -> 6.78 | N9: =SUMIFS(Tasas!$C$5:$C$36,Tasas!$A$5:$A$36,N$4,Tasas!$B$5:$B$36,I9) -> 7 | O9: =SUMIFS(Tasas!$C$5:$C$36,Tasas!$A$5:$A$36,O$4,Tasas!$B$5:$B$36,J9) -> 7.94 | P9: =SUMIFS(Tasas!$E$5:$E$36,Tasas!$A$5:$A$36,P$4,Tasas!$B$5:$B$36,F9) -> 28 | Q9: =SUMIFS(Tasas!$E$5:$E$36,Tasas!$A$5:$A$36,Q$4,Tasas!$B$5:$B$36,G9) -> 91 | R9: =SUMIFS(Tasas!$E$5:$E$36,Tasas!$A$5:$A$36,R$4,Tasas!$B$5:$B$36,H9) -> 175 | S9: =SUMIFS(Tasas!$E$5:$E$36,Tasas!$A$5:$A$36,S$4,Tasas!$B$5:$B$36,I9) -> 350 | T9: =SUMIFS(Tasas!$E$5:$E$36,Tasas!$A$5:$A$36,T$4,Tasas!$B$5:$B$36,J9) -> 693 | U9: =IF($E9<=MIN($P9:$T9),MIN($P9:$T9),_xlfn.MAXIFS($P9:$T9,$P9:$T9,"<="&$E9)) -> 28 | V9: =IF($E9>=MAX($P9:$T9),MAX($P9:$T9),_xlfn.MINIFS($P9:$T9,$P9:$T9,">="&$E9)) -> 28 | W9: =INDEX($P$4:$T$4,MATCH(U9,$P9:$T9,0)) -> 28 | X9: =INDEX($P$4:$T$4,MATCH(V9,$P9:$T9,0)) -> 28 | Y9: =INDEX($F9:$J9,MATCH(U9,$P9:$T9,0)) -> 46275 | Z9: =INDEX($F9:$J9,MATCH(V9,$P9:$T9,0)) -> 46275 | AA9: =INDEX($K9:$O9,MATCH(U9,$P9:$T9,0)) -> 6.25 | AB9: =INDEX($K9:$O9,MATCH(V9,$P9:$T9,0)) -> 6.25 | AC9: =IF(E9<MIN($P9:$T9),"extremo inferior",IF(E9>MAX($P9:$T9),"extremo superior",IF(U9=V9,"nodo","interpolación"))) -> extremo inferior | AD9: =IF(U9=V9,AA9,AA9+(AB9-AA9)*(E9-U9)/(V9-U9)) -> 6.25 | AE9: =D9/(1+AD9/100*E9/360) -> 9.9585062 | AF9: =ROUND(AE9,7) -> 9.9585062 | AG9: =A9&"|"&B9 -> 46279|BI261008
A10: 46280 | B10: BI261008 | C10: =INDEX(Entradas!$F$40:$F$46,MATCH(B10,Entradas!$A$40:$A$46,0)) -> 46303 | D10: =INDEX(Entradas!$G$40:$G$46,MATCH(B10,Entradas!$A$40:$A$46,0)) -> 10 | E10: =C10-A10 -> 23 | F10: =_xlfn.MAXIFS(Tasas!$B$5:$B$36,Tasas!$A$5:$A$36,F$4,Tasas!$B$5:$B$36,"<="&$A10) -> 46275 | G10: =_xlfn.MAXIFS(Tasas!$B$5:$B$36,Tasas!$A$5:$A$36,G$4,Tasas!$B$5:$B$36,"<="&$A10) -> 46275 | H10: =_xlfn.MAXIFS(Tasas!$B$5:$B$36,Tasas!$A$5:$A$36,H$4,Tasas!$B$5:$B$36,"<="&$A10) -> 46275 | I10: =_xlfn.MAXIFS(Tasas!$B$5:$B$36,Tasas!$A$5:$A$36,I$4,Tasas!$B$5:$B$36,"<="&$A10) -> 46268 | J10: =_xlfn.MAXIFS(Tasas!$B$5:$B$36,Tasas!$A$5:$A$36,J$4,Tasas!$B$5:$B$36,"<="&$A10) -> 46275 | K10: =SUMIFS(Tasas!$C$5:$C$36,Tasas!$A$5:$A$36,K$4,Tasas!$B$5:$B$36,F10) -> 6.25 | L10: =SUMIFS(Tasas!$C$5:$C$36,Tasas!$A$5:$A$36,L$4,Tasas!$B$5:$B$36,G10) -> 6.56 | M10: =SUMIFS(Tasas!$C$5:$C$36,Tasas!$A$5:$A$36,M$4,Tasas!$B$5:$B$36,H10) -> 6.78 | N10: =SUMIFS(Tasas!$C$5:$C$36,Tasas!$A$5:$A$36,N$4,Tasas!$B$5:$B$36,I10) -> 7 | O10: =SUMIFS(Tasas!$C$5:$C$36,Tasas!$A$5:$A$36,O$4,Tasas!$B$5:$B$36,J10) -> 7.94 | P10: =SUMIFS(Tasas!$E$5:$E$36,Tasas!$A$5:$A$36,P$4,Tasas!$B$5:$B$36,F10) -> 28 | Q10: =SUMIFS(Tasas!$E$5:$E$36,Tasas!$A$5:$A$36,Q$4,Tasas!$B$5:$B$36,G10) -> 91 | R10: =SUMIFS(Tasas!$E$5:$E$36,Tasas!$A$5:$A$36,R$4,Tasas!$B$5:$B$36,H10) -> 175 | S10: =SUMIFS(Tasas!$E$5:$E$36,Tasas!$A$5:$A$36,S$4,Tasas!$B$5:$B$36,I10) -> 350 | T10: =SUMIFS(Tasas!$E$5:$E$36,Tasas!$A$5:$A$36,T$4,Tasas!$B$5:$B$36,J10) -> 693 | U10: =IF($E10<=MIN($P10:$T10),MIN($P10:$T10),_xlfn.MAXIFS($P10:$T10,$P10:$T10,"<="&$E10)) -> 28 | V10: =IF($E10>=MAX($P10:$T10),MAX($P10:$T10),_xlfn.MINIFS($P10:$T10,$P10:$T10,">="&$E10)) -> 28 | W10: =INDEX($P$4:$T$4,MATCH(U10,$P10:$T10,0)) -> 28 | X10: =INDEX($P$4:$T$4,MATCH(V10,$P10:$T10,0)) -> 28 | Y10: =INDEX($F10:$J10,MATCH(U10,$P10:$T10,0)) -> 46275 | Z10: =INDEX($F10:$J10,MATCH(V10,$P10:$T10,0)) -> 46275 | AA10: =INDEX($K10:$O10,MATCH(U10,$P10:$T10,0)) -> 6.25 | AB10: =INDEX($K10:$O10,MATCH(V10,$P10:$T10,0)) -> 6.25 | AC10: =IF(E10<MIN($P10:$T10),"extremo inferior",IF(E10>MAX($P10:$T10),"extremo superior",IF(U10=V10,"nodo","interpolación"))) -> extremo inferior | AD10: =IF(U10=V10,AA10,AA10+(AB10-AA10)*(E10-U10)/(V10-U10)) -> 6.25 | AE10: =D10/(1+AD10/100*E10/360) -> 9.9602283 | AF10: =ROUND(AE10,7) -> 9.9602283 | AG10: =A10&"|"&B10 -> 46280|BI261008
A11: 46281 | B11: BI261008 | C11: =INDEX(Entradas!$F$40:$F$46,MATCH(B11,Entradas!$A$40:$A$46,0)) -> 46303 | D11: =INDEX(Entradas!$G$40:$G$46,MATCH(B11,Entradas!$A$40:$A$46,0)) -> 10 | E11: =C11-A11 -> 22 | F11: =_xlfn.MAXIFS(Tasas!$B$5:$B$36,Tasas!$A$5:$A$36,F$4,Tasas!$B$5:$B$36,"<="&$A11) -> 46275 | G11: =_xlfn.MAXIFS(Tasas!$B$5:$B$36,Tasas!$A$5:$A$36,G$4,Tasas!$B$5:$B$36,"<="&$A11) -> 46275 | H11: =_xlfn.MAXIFS(Tasas!$B$5:$B$36,Tasas!$A$5:$A$36,H$4,Tasas!$B$5:$B$36,"<="&$A11) -> 46275 | I11: =_xlfn.MAXIFS(Tasas!$B$5:$B$36,Tasas!$A$5:$A$36,I$4,Tasas!$B$5:$B$36,"<="&$A11) -> 46268 | J11: =_xlfn.MAXIFS(Tasas!$B$5:$B$36,Tasas!$A$5:$A$36,J$4,Tasas!$B$5:$B$36,"<="&$A11) -> 46275 | K11: =SUMIFS(Tasas!$C$5:$C$36,Tasas!$A$5:$A$36,K$4,Tasas!$B$5:$B$36,F11) -> 6.25 | L11: =SUMIFS(Tasas!$C$5:$C$36,Tasas!$A$5:$A$36,L$4,Tasas!$B$5:$B$36,G11) -> 6.56 | M11: =SUMIFS(Tasas!$C$5:$C$36,Tasas!$A$5:$A$36,M$4,Tasas!$B$5:$B$36,H11) -> 6.78 | N11: =SUMIFS(Tasas!$C$5:$C$36,Tasas!$A$5:$A$36,N$4,Tasas!$B$5:$B$36,I11) -> 7 | O11: =SUMIFS(Tasas!$C$5:$C$36,Tasas!$A$5:$A$36,O$4,Tasas!$B$5:$B$36,J11) -> 7.94 | P11: =SUMIFS(Tasas!$E$5:$E$36,Tasas!$A$5:$A$36,P$4,Tasas!$B$5:$B$36,F11) -> 28 | Q11: =SUMIFS(Tasas!$E$5:$E$36,Tasas!$A$5:$A$36,Q$4,Tasas!$B$5:$B$36,G11) -> 91 | R11: =SUMIFS(Tasas!$E$5:$E$36,Tasas!$A$5:$A$36,R$4,Tasas!$B$5:$B$36,H11) -> 175 | S11: =SUMIFS(Tasas!$E$5:$E$36,Tasas!$A$5:$A$36,S$4,Tasas!$B$5:$B$36,I11) -> 350 | T11: =SUMIFS(Tasas!$E$5:$E$36,Tasas!$A$5:$A$36,T$4,Tasas!$B$5:$B$36,J11) -> 693 | U11: =IF($E11<=MIN($P11:$T11),MIN($P11:$T11),_xlfn.MAXIFS($P11:$T11,$P11:$T11,"<="&$E11)) -> 28 | V11: =IF($E11>=MAX($P11:$T11),MAX($P11:$T11),_xlfn.MINIFS($P11:$T11,$P11:$T11,">="&$E11)) -> 28 | W11: =INDEX($P$4:$T$4,MATCH(U11,$P11:$T11,0)) -> 28 | X11: =INDEX($P$4:$T$4,MATCH(V11,$P11:$T11,0)) -> 28 | Y11: =INDEX($F11:$J11,MATCH(U11,$P11:$T11,0)) -> 46275 | Z11: =INDEX($F11:$J11,MATCH(V11,$P11:$T11,0)) -> 46275 | AA11: =INDEX($K11:$O11,MATCH(U11,$P11:$T11,0)) -> 6.25 | AB11: =INDEX($K11:$O11,MATCH(V11,$P11:$T11,0)) -> 6.25 | AC11: =IF(E11<MIN($P11:$T11),"extremo inferior",IF(E11>MAX($P11:$T11),"extremo superior",IF(U11=V11,"nodo","interpolación"))) -> extremo inferior | AD11: =IF(U11=V11,AA11,AA11+(AB11-AA11)*(E11-U11)/(V11-U11)) -> 6.25 | AE11: =D11/(1+AD11/100*E11/360) -> 9.9619509 | AF11: =ROUND(AE11,7) -> 9.9619509 | AG11: =A11&"|"&B11 -> 46281|BI261008
